// Handles are defined as unsigned in Rust, but that's doesn't work well with JNA.
// We can pretend its signed since Rust handles are opaque values and Kotlin handles don't use all
// 64 bits.
typealias UniffiHandle = Long

// A handful of classes and functions to support the generated data structures.
// This would be a good candidate for isolating in its own ffi-support lib.
// Error runtime.
@Structure.FieldOrder("code", "error_buf")
internal open class RustCallStatus : Structure() {
    @JvmField var code: Byte = 0
    @JvmField var error_buf: RustBuffer.ByValue = RustBuffer.ByValue()

    class ByValue: RustCallStatus(), Structure.ByValue

    fun isSuccess(): Boolean {
        return code == 0.toByte()
    }

    fun isError(): Boolean {
        return code == 1.toByte()
    }

    fun isPanic(): Boolean {
        return code == 2.toByte()
    }
}

class InternalException(message: String) : Exception(message)

// Each top-level error class has a companion object that can lift the error from the call status's rust buffer
interface CallStatusErrorHandler<E> {
    fun lift(error_buf: RustBuffer.ByValue): E;
}

// Helpers for calling Rust
// In practice we usually need to be synchronized to call this safely, so it doesn't
// synchronize itself

// Call a rust function that returns a Result<>.  Pass in the Error class companion that corresponds to the Err
private inline fun <U, E: Exception> rustCallWithError(errorHandler: CallStatusErrorHandler<E>, callback: (RustCallStatus) -> U): U {
    var status = RustCallStatus();
    val return_value = callback(status)
    checkCallStatus(errorHandler, status)
    return return_value
}

// Check RustCallStatus and throw an error if the call wasn't successful
private fun<E: Exception> checkCallStatus(errorHandler: CallStatusErrorHandler<E>, status: RustCallStatus) {
    if (status.isSuccess()) {
        return
    } else if (status.isError()) {
        throw errorHandler.lift(status.error_buf)
    } else if (status.isPanic()) {
        // when the rust code sees a panic, it tries to construct a rustbuffer
        // with the message.  but if that code panics, then it just sends back
        // an empty buffer.
        if (status.error_buf.len > 0) {
            throw InternalException({{ Type::String.borrow()|lift_fn }}(status.error_buf))
        } else {
            throw InternalException("Rust panic")
        }
    } else {
        throw InternalException("Unknown rust call status: $status.code")
    }
}

// CallStatusErrorHandler implementation for times when we don't expect a CALL_ERROR
object NullCallStatusErrorHandler: CallStatusErrorHandler<InternalException> {
    override fun lift(error_buf: RustBuffer.ByValue): InternalException {
        RustBuffer.free(error_buf)
        return InternalException("Unexpected CALL_ERROR")
    }
}

// Call a rust function that returns a plain value
private inline fun <U> rustCall(callback: (RustCallStatus) -> U): U {
    return rustCallWithError(NullCallStatusErrorHandler, callback);
}

// FFI type for Rust future continuations
internal interface UniFffiRustFutureContinuationCallbackType : com.sun.jna.Callback {
    fun callback(continuationHandle: Long, pollResult: Short);
}
